Workbook

Sheet Daily
B1: # of times he used replacement behavior (#of times replacement was used/#of elevated intervals) | C1: (# of R/# elevated intervals) | D1: Percentage of Yes (Yes/# of elevated intervals) | E1: Percentage (Mild/ Total interals) | F1: Percentage (Moderate/ Total interals) | G1: Percentage (Severe/ Total interals) | H1: Percentage # intervals behavior exhibited/ Total # Intervals
A2: Date | B2: Used Replacement Behavior | C2: How many replacement behaviors did he request? | D2: Did he name an accurate emotion? | E2: Elopement Mild | F2: Elopement Moderate | G2: Elopement Severe | H2: Behaviors Exhibited | I2: Comments
A3: 45902 | B3: =4/4 -> 1 | C3: =1/4 -> 0.25 | D3: =0/4 -> 0 | E3: =0 -> 0 | F3: =0 -> 0 | G3: =0 -> 0 | H3: =0 -> 0
A4: 45903 | B4: =4/6 -> 0.66666667 | C4: =3/6 -> 0.5 | D4: =0/6 -> 0 | E4: =1/13 -> 0.076923077 | F4: =0 -> 0 | G4: =0 -> 0 | H4: =1/13 -> 0.076923077
A5: 45904 | B5: =6/6 -> 1 | C5: =2/6 -> 0.33333333 | D5: =4/6 -> 0.66666667 | E5: =0 -> 0 | F5: =0 -> 0 | G5: =0 -> 0 | H5: =0 -> 0
A6: 45905 | B6: =5/6 -> 0.83333333 | C6: =1/6 -> 0.16666667 | D6: =0/6 -> 0 | E6: =1/13 -> 0.076923077 | F6: =0 -> 0 | G6: =0 -> 0 | H6: =1/13 -> 0.076923077
A7: 9/2/25 Weekly Total | B7: =AVERAGE(B3:B6) -> 0.875 | C7: =AVERAGE(C3:C6) -> 0.3125 | D7: =AVERAGE(D3:D6) -> 0.16666667 | E7: =AVERAGE(E3:E6) -> 0.038461538 | F7: =AVERAGE(F3:F6) -> 0 | G7: =AVERAGE(G3:G6) -> 0 | H7: =AVERAGE(H3:H6) -> 0.038461538
A8: 45908 | B8: =1/1 -> 1 | C8: =0/1 -> 0 | D8: =0/1 -> 0 | E8: =0 -> 0 | F8: =0 -> 0 | G8: =0 -> 0 | H8: =0 -> 0
A9: 45909 | B9: =4/6 -> 0.66666667 | C9: =1/6 -> 0.16666667 | D9: =2/7 -> 0.28571429 | E9: =1/13 -> 0.076923077 | F9: =0 -> 0 | G9: =0 -> 0 | H9: =1/13 -> 0.076923077
A10: 45910 | B10: =4/4 -> 1 | C10: =2/4 -> 0.5 | D10: =2/4 -> 0.5 | E10: =0 -> 0 | F10: =1/13 -> 0.076923077 | G10: =0 -> 0 | H10: =0 -> 0
A11: 45911 | B11: =1/2 -> 0.5 | C11: =1/2 -> 0.5 | D11: =3/4 -> 0.75 | E11: 0 | F11: 0 | G11: 0
A12: 45912 | B12: =3/3 -> 1 | C12: =2/3 -> 0.66666667 | D12: =1/3 -> 0.33333333 | E12: =1/10 -> 0.1 | F12: =0/10 -> 0 | G12: =0/10 -> 0 | H12: =1/10 -> 0.1 | I12: left early (1:45)
A13: 9/8/25 Weekly Total | B13: =AVERAGE(B8:B12) -> 0.83333333 | C13: =AVERAGE(C8:C12) -> 0.36666667 | D13: =AVERAGE(D8:D12) -> 0.37380952 | E13: =AVERAGE(E8:E12) -> 0.035384615 | F13: =AVERAGE(F8:F12) -> 0.015384615 | G13: =AVERAGE(G8:G12) -> 0 | H13: =AVERAGE(H8:H12) -> 0.044230769
A14: 45915 | B14: =1/3 -> 0.33333333 | C14: =0/3 -> 0 | D14: =1/4 -> 0.25 | E14: =1/13 -> 0.076923077 | F14: =0/13 -> 0 | G14: =0/13 -> 0 | H14: =0/13 -> 0
A15: 45916 | B15: =3/6 -> 0.5 | C15: =0/6 -> 0 | D15: =2/6 -> 0.33333333 | E15: =3/13 -> 0.23076923 | F15: =1/13 -> 0.076923077 | G15: =0/13 -> 0 | H15: =2/13 -> 0.15384615
A16: 45917 | D16: =0/3 -> 0 | E16: =0/13 -> 0 | F16: =0/13 -> 0 | G16: =0/13 -> 0 | H16: =1/13 -> 0.076923077 | I16: *no data on replacement behaviors taken
A17: 45918 | B17: =5/13 -> 0.38461538 | C17: =0/2 -> 0 | D17: =0/3 -> 0 | E17: =2/13 -> 0.15384615 | F17: =1/13 -> 0.076923077 | G17: =0/13 -> 0 | H17: =1/13 -> 0.076923077
A18: 45919 | B18: =2/3 -> 0.66666667 | C18: =1/3 -> 0.33333333 | D18: =0/3 -> 0 | E18: =1/13 -> 0.076923077 | F18: =1/13 -> 0.076923077 | G18: =0/13 -> 0 | H18: =1/13 -> 0.076923077
A19: 9/15/25 Weekly Total | B19: =AVERAGE(B14:B18) -> 0.47115385 | C19: =AVERAGE(C14:C18) -> 0.083333333 | D19: =AVERAGE(D14:D18) -> 0.11666667 | E19: =AVERAGE(E14:E18) -> 0.10769231 | F19: =AVERAGE(F14:F18) -> 0.046153846 | G19: =AVERAGE(G14:G18) -> 0 | H19: =AVERAGE(H14:H18) -> 0.076923077
A20: 45922 | B20: =2/4 -> 0.5 | C20: =2/4 -> 0.5 | D20: 0.25 | E20: =1/13 -> 0.076923077 | F20: =0/13 -> 0 | G20: =0/13 -> 0 | H20: =2/13 -> 0.15384615
A21: 45923 | B21: =2/4 -> 0.5 | C21: =0/4 -> 0 | D21: =1/4 -> 0.25 | E21: =2/13 -> 0.15384615 | F21: =1/13 -> 0.076923077 | G21: =0/13 -> 0 | H21: =1/13 -> 0.076923077
A22: 45924 | B22: =2/4 -> 0.5 | C22: =0/4 -> 0 | D22: =0/4 -> 0 | E22: =2/13 -> 0.15384615 | F22: =2/13 -> 0.15384615 | G22: =0/13 -> 0 | H22: =3/13 -> 0.23076923
A23: 45925 | B23: =2/3 -> 0.66666667 | C23: =1/3 -> 0.33333333 | D23: =2/4 -> 0.5 | E23: =1/13 -> 0.076923077 | F23: =1/13 -> 0.076923077 | G23: =0/13 -> 0 | H23: 0.0769
A24: 45926 | B24: =0/13 -> 0 | C24: =0/13 -> 0 | D24: =1/3 -> 0.33333333 | E24: =0/13 -> 0 | F24: =2/13 -> 0.15384615 | G24: =0/13 -> 0 | H24: =4/13 -> 0.30769231
A25: 9/22/25 Weekly Total | B25: =AVERAGE(B20:B24) -> 0.43333333 | C25: =AVERAGE(C20:C24) -> 0.16666667 | D25: =AVERAGE(D20:D24) -> 0.26666667 | E25: =AVERAGE(E20:E24) -> 0.092307692 | F25: =AVERAGE(F20:F24) -> 0.092307692 | G25: =AVERAGE(G20:G24) -> 0 | H25: =AVERAGE(H20:H24) -> 0.16922615
A26: 45929 | B26: =2/3 -> 0.66666667 | C26: =1/3 -> 0.33333333 | D26: =2/3 -> 0.66666667 | E26: =1/13 -> 0.076923077 | F26: =1/13 -> 0.076923077 | G26: =0/13 -> 0 | H26: =4/13 -> 0.30769231
A27: 45930 | B27: =2/4 -> 0.5 | C27: =0/4 -> 0 | D27: =1/5 -> 0.2 | E27: =1/13 -> 0.076923077 | F27: =1/13 -> 0.076923077 | G27: =1/13 -> 0.076923077 | H27: =4/13 -> 0.30769231
A28: 45931 | B28: =1/4 -> 0.25 | C28: =0/4 -> 0 | D28: =2/4 -> 0.5 | E28: =1/13 -> 0.076923077 | F28: =2/13 -> 0.15384615 | G28: =0/13 -> 0 | H28: =3/13 -> 0.23076923
A29: 45932 | B29: =3/4 -> 0.75 | C29: =1/4 -> 0.25 | D29: =2/4 -> 0.5 | E29: =0/4 -> 0 | F29: =3/13 -> 0.23076923 | G29: =0/13 -> 0 | H29: =1/13 -> 0.076923077
A30: 45933 | B30: =1/2 -> 0.5 | C30: =0/2 -> 0 | D30: =1/2 -> 0.5 | E30: =0/13 -> 0 | F30: =0/13 -> 0 | G30: =0/13 -> 0 | H30: =2/13 -> 0.15384615
A31: 9/29/25 Weekly Total | B31: =AVERAGE(B26:B30) -> 0.53333333 | C31: =AVERAGE(C26:C30) -> 0.11666667 | D31: =AVERAGE(D26:D30) -> 0.47333333 | E31: =AVERAGE(E26:E30) -> 0.046153846 | F31: =AVERAGE(F26:F30) -> 0.10769231 | G31: =AVERAGE(G26:G30) -> 0.015384615 | H31: =AVERAGE(H26:H30) -> 0.21538462
A32: 45937 | B32: =1/1 -> 1 | C32: =1/1 -> 1 | D32: =1/1 -> 1 | E32: =0/8 -> 0 | F32: =0/8 -> 0 | G32: =0/8 -> 0 | H32: =0/8 -> 0 | I32: Left early
A33: 45938 | B33: =1/4 -> 0.25 | C33: =1/4 -> 0.25 | D33: =2/6 -> 0.33333333 | E33: =1/13 -> 0.076923077 | F33: =0/13 -> 0 | G33: =0/13 -> 0 | H33: =2/13 -> 0.15384615 | I33: Declined scheduled break
A34: 45939 | B34: =1/5 -> 0.2 | C34: =0/5 -> 0 | D34: =0/5 -> 0 | E34: =1/13 -> 0.076923077 | F34: =0/13 -> 0 | G34: =0/13 -> 0 | H34: =1/13 -> 0.076923077 | I34: Declined scheduled break
A35: 45940 | B35: =2/4 -> 0.5 | C35: =1/4 -> 0.25 | D35: =0/6 -> 0 | E35: =0/13 -> 0 | F35: =3/13 -> 0.23076923 | G35: =0/13 -> 0 | H35: =0/13 -> 0
A36: 10/7/25 Weekly Total | B36: =AVERAGE(B32:B35) -> 0.4875 | C36: =AVERAGE(C32:C35) -> 0.375 | D36: =AVERAGE(D32:D35) -> 0.33333333 | E36: =AVERAGE(E32:E35) -> 0.038461538 | F36: =AVERAGE(F32:F35) -> 0.057692308 | G36: =AVERAGE(G32:G35) -> 0 | H36: =AVERAGE(H32:H35) -> 0.057692308
A37: 45943 | B37: =1/6 -> 0.16666667 | C37: =0/6 -> 0 | D37: =0/6 -> 0 | E37: =0/13 -> 0 | F37: =5/13 -> 0.38461538 | G37: =0/13 -> 0 | H37: =3/13 -> 0.23076923
A38: 45944 | B38: =1/3 -> 0.33333333 | C38: =0/13 -> 0 | D38: =1/3 -> 0.33333333 | E38: =0/13 -> 0 | F38: =0/13 -> 0 | G38: =0/13 -> 0 | H38: =2/13 -> 0.15384615
A39: 45945 | B39: =1/2 -> 0.5 | C39: =1/2 -> 0.5 | D39: =1/2 -> 0.5 | E39: =0/13 -> 0 | F39: =1/13 -> 0.076923077 | G39: =0/13 -> 0 | H39: =0/13 -> 0
A40: 10/13/25 Weekly Total | B40: =AVERAGE(B37:B39) -> 0.33333333 | C40: =AVERAGE(C37:C39) -> 0.16666667 | D40: =AVERAGE(D37:D39) -> 0.27777778 | E40: =AVERAGE(E37:E39) -> 0 | F40: =AVERAGE(F37:F39) -> 0.15384615 | G40: =AVERAGE(G37:G39) -> 0 | H40: =AVERAGE(H37:H39) -> 0.12820513
...

Sheet Weekly
A1: Date | B1: Used Replacement Behavior | C1: How many replacement behaviors did he request? | D1: Did he name an accurate emotion? | E1: Elopement Mild | F1: Elopement Moderate | G1: Elopement Severe | H1: Behaviors Exhibited (Physical aggression, Property destruction, verbal outbursts) | I1: Comments
A2: Totals | B2: =Averageif(B4:B17, ">0") -> 0.49606881 | C2: =Averageif(C4:C17, ">0") -> 0.22088435 | D2: =Averageif(D4:D17, ">0") -> 0.29811224 | E2: =Averageif(E4:E17, ">0") -> 0.070927022 | F2: =Averageif(F4:F17, ">0") -> 0.093648915 | G2: =Averageif(G4:G17, ">0") -> 0.015384615 | H2: =Averageif(H4:H17, ">0") -> 0.098305531
A3: Percentages | B3: =averageif(B4:B40, ">0") -> 0.53037876 | C3: =averageif(C4:C40, ">0") -> 0.24905837 | D3: =averageif(D4:D40, ">0") -> 0.31871981 | E3: =averageif(E4:E40, ">0") -> 0.073928571 | F3: =averageif(F4:F40, ">0") -> 0.10118457 | G3: =averageif(G4:G40, ">0") -> 0.015934066 | H3: =averageif(H4:H40, ">0") -> 0.12072862
A4: =Daily!A7 -> 9/2/25 Weekly Total | B4: =Daily!B7 -> 0.875 | C4: =Daily!C7 -> 0.3125 | D4: =Daily!D7 -> 0.16666667 | E4: =Daily!E7 -> 0.038461538 | F4: =Daily!F7 -> 0 | G4: =Daily!G7 -> 0 | H4: =Daily!H7 -> 0.038461538 | I4: =Daily!I7
A5: =Daily!A13 -> 9/8/25 Weekly Total | B5: =Daily!B13 -> 0.83333333 | C5: =Daily!C13 -> 0.36666667 | D5: =Daily!D13 -> 0.37380952 | E5: =Daily!E13 -> 0.035384615 | F5: =Daily!F13 -> 0.015384615 | G5: =Daily!G13 -> 0 | H5: =Daily!H13 -> 0.044230769 | I5: =Daily!I13
A6: =Daily!A19 -> 9/15/25 Weekly Total | B6: =Daily!B19 -> 0.47115385 | C6: =Daily!C19 -> 0.083333333 | D6: =Daily!D19 -> 0.11666667 | E6: =Daily!E19 -> 0.10769231 | F6: =Daily!F19 -> 0.046153846 | G6: =Daily!G19 -> 0 | H6: =Daily!H19 -> 0.076923077 | I6: =Daily!I19
A7: =Daily!A25 -> 9/22/25 Weekly Total | B7: =Daily!B25 -> 0.43333333 | C7: =Daily!C25 -> 0.16666667 | D7: =Daily!D25 -> 0.26666667 | E7: =Daily!E25 -> 0.092307692 | F7: =Daily!F25 -> 0.092307692 | G7: =Daily!G25 -> 0 | H7: =Daily!H25 -> 0.16922615 | I7: =Daily!I25
A8: =Daily!A31 -> 9/29/25 Weekly Total | B8: =Daily!B31 -> 0.53333333 | C8: =Daily!C31 -> 0.11666667 | D8: =Daily!D31 -> 0.47333333 | E8: =Daily!E31 -> 0.046153846 | F8: =Daily!F31 -> 0.10769231 | G8: =Daily!G31 -> 0.015384615 | H8: =Daily!H31 -> 0.21538462 | I8: =Daily!I31
A9: =Daily!A36 -> 10/7/25 Weekly Total | B9: =Daily!B36 -> 0.4875 | C9: =Daily!C36 -> 0.375 | D9: =Daily!D36 -> 0.33333333 | E9: =Daily!E36 -> 0.038461538 | F9: =Daily!F36 -> 0.057692308 | G9: =Daily!G36 -> 0 | H9: =Daily!H36 -> 0.057692308 | I9: =Daily!I36
A10: =Daily!A40 -> 10/13/25 Weekly Total | B10: =Daily!B40 -> 0.33333333 | C10: =Daily!C40 -> 0.16666667 | D10: =Daily!D40 -> 0.27777778 | E10: =Daily!E40 -> 0 | F10: =Daily!F40 -> 0.15384615 | G10: =Daily!G40 -> 0 | H10: =Daily!H40 -> 0.12820513 | I10: =Daily!I40
A11: =Daily!A45 -> 10/21/25 Weekly Total | B11: =Daily!B45 -> 0.39583333 | C11: =Daily!C45 -> 0.0625 | D11: =Daily!D45 -> 0.33333333 | E11: =Daily!E45 -> 0.096153846 | F11: =Daily!F45 -> 0.076923077 | G11: =Daily!G45 -> 0 | H11: =Daily!H45 -> 0.076923077 | I11: =Daily!I45
A12: =Daily!A51 -> 10/27/25 Weekly Total | B12: =Daily!B51 -> 0.16666667 | C12: =Daily!C51 -> 0.13333333 | D12: =Daily!D51 -> 0.22666667 | E12: =Daily!E51 -> 0.061538462 | F12: =Daily!F51 -> 0.10769231 | G12: =Daily!G51 -> 0 | H12: =Daily!H51 -> 0.092307692 | I12: =Daily!I51
A13: =Daily!A57 -> 11/3/25 Weekly Total | B13: =Daily!B57 -> 0.23 | C13: =Daily!C57 -> 0.13 | D13: =Daily!D57 -> 0.32 | E13: =Daily!E57 -> 0.076923077 | F13: =Daily!F57 -> 0.12307692 | G13: =Daily!G57 -> 0 | H13: =Daily!H57 -> 0.092307692 | I13: =Daily!I57
A14: =Daily!A63 -> 11/10/25 Weekly Total | B14: =Daily!B63 -> 0.56666667 | C14: =Daily!C63 -> 0.33333333 | D14: =Daily!D63 -> 0.28666667 | E14: =Daily!E63 -> 0.035384615 | F14: =Daily!F63 -> 0.096923077 | G14: =Daily!G63 -> 0.015384615 | H14: =Daily!H63 -> 0.092307692 | I14: =Daily!I63
A15: =Daily!A69 -> 11/17/25 Weekly Total | B15: =Daily!B69 -> 0.41428571 | C15: =Daily!C69 -> 0.53714286 | D15: =Daily!D69 -> 0.28571429 | E15: =Daily!E69 -> 0.10769231 | F15: =Daily!F69 -> 0.061538462 | G15: =Daily!G69 -> 0.015384615 | H15: =Daily!H69 -> 0.076923077 | I15: =Daily!I69
A16: =Daily!A75 -> 12/1/25 Weekly Total | B16: =Daily!B75 -> 0.56 | C16: =Daily!C75 -> 0.14833333 | D16: =Daily!D75 -> 0.36571429 | E16: =Daily!E75 -> 0.092307692 | F16: =Daily!F75 -> 0.16923077 | G16: =Daily!G75 -> 0 | H16: =Daily!H75 -> 0.076923077 | I16: =Daily!I75
A17: =Daily!A81 -> 12/8/25 Weekly Total | B17: =Daily!B81 -> 0.64452381 | C17: =Daily!C81 -> 0.1602381 | D17: =Daily!D81 -> 0.34722222 | E17: =Daily!E81 -> 0.093589744 | F17: =Daily!F81 -> 0.10897436 | G17: =Daily!G81 -> 0.015384615 | H17: =Daily!H81 -> 0.13846154 | I17: =Daily!I81
A18: =Daily!A87 -> 12/15/25 Weekly Total | B18: =Daily!B87 -> 0.33333333 | C18: =Daily!C87 -> 0.09375 | D18: =Daily!D87 -> 0.40833333 | E18: =Daily!E87 -> 0.041666667 | F18: =Daily!F87 -> 0.19551282 | G18: =Daily!G87 -> 0 | H18: =Daily!H87 -> 0.22275641 | I18: =Daily!I87
A19: =Daily!A90 -> 12/22/25 Weekly Total | B19: =Daily!B90 -> 0.78571429 | C19: =Daily!C90 -> 0.64285714 | D19: =Daily!D90 -> 0.28571429 | E19: =Daily!E90 -> 0 | F19: =Daily!F90 -> 0.11538462 | G19: =Daily!G90 -> 0 | H19: =Daily!H90 -> 0.11538462 | I19: =Daily!I90
A20: =Daily!A96 -> 1/5/26 Weekly Total | B20: =Daily!B96 -> 0.77857143 | C20: =Daily!C96 -> 0.38571429 | D20: =Daily!D96 -> 0.225 | E20: =Daily!E96 -> 0.038461538 | F20: =Daily!F96 -> 0.09965035 | G20: =Daily!G96 -> 0.019230769 | H20: =Daily!H96 -> 0.096153846 | I20: =Daily!I96
A21: =Daily!A102 -> 1/12/26 Weekly Total | B21: =Daily!B102 -> 0.33333333 | C21: =Daily!C102 -> 0.18333333 | D21: =Daily!D102 -> 0.33 | E21: =Daily!E102 -> 0.15384615 | F21: =Daily!F102 -> 0.061538462 | G21: =Daily!G102 -> 0 | H21: =Daily!H102 -> 0.10769231 | I21: =Daily!I102
A22: =Daily!A107 -> 1/20/26 Weekly Total | B22: =Daily!B107 -> 0.5 | C22: =Daily!C107 -> 0.33333333 | D22: =Daily!D107 -> 0.22222222 | E22: =Daily!E107 -> 0 | F22: =Daily!F107 -> 0.076923077 | G22: =Daily!G107 -> 0 | H22: =Daily!H107 -> 0.13589744 | I22: =Daily!I107
A23: =Daily!A113 -> 1/26/26 Weekly Total | B23: =Daily!B113 -> 0.48095238 | C23: =Daily!C113 -> 0.057142857 | D23: =Daily!D113 -> 0.18571429 | E23: =Daily!E113 -> 0.061538462 | F23: =Daily!F113 -> 0.16923077 | G23: =Daily!G113 -> 0.015384615 | H23: =Daily!H113 -> 0.27692308 | I23: =Daily!I113
A24: =Daily!A119 -> 2/2/26 Weekly Total | B24: =Daily!B119 -> 0.35 | C24: =Daily!C119 -> 0.3 | D24: =Daily!D119 -> 0 | E24: =Daily!E119 -> 0.032051282 | F24: =Daily!F119 -> 0.030769231 | G24: =Daily!G119 -> 0.015384615 | H24: =Daily!H119 -> 0.11153846 | I24: =Daily!I119
A25: =Daily!A125 -> 2/9/26 Weekly Total | B25: =Daily!B125 -> 0.47777778 | C25: =Daily!C125 -> 0.17777778 | D25: =Daily!D125 -> 0.31666667 | E25: =Daily!E125 -> 0.057692308 | F25: =Daily!F125 -> 0.17692308 | G25: =Daily!G125 -> 0 | H25: =Daily!H125 -> 0.22115385 | I25: =Daily!I125
A26: =Daily!A129 -> 2/17/26 Weekly Total | B26: =Daily!B129 -> 0.74444444 | C26: =Daily!C129 -> 0.37777778 | D26: =Daily!D129 -> 0.51666667 | E26: =Daily!E129 -> 0.014423077 | F26: =Daily!F129 -> 0.082692308 | G26: =Daily!G129 -> 0 | H26: =Daily!H129 -> 0.11298077 | I26: =Daily!I129
A27: =Daily!A135 -> 2/23/26 Weekly Total | B27: =Daily!B135 -> 1 | C27: =Daily!C135 -> 0.33333333 | D27: =Daily!D135 -> 0.66666667 | E27: =Daily!E135 -> 0.23076923 | F27: =Daily!F135 -> 0 | G27: =Daily!G135 -> 0 | H27: =Daily!H135 -> 0 | I27: =Daily!I135
A28: =Daily!A140 -> 3/2/26 Weekly Total | B28: =Daily!B140 -> #DIV/0! | C28: =Daily!C140 -> #DIV/0! | D28: =Daily!D140 -> #DIV/0! | E28: =Daily!E140 -> #DIV/0! | F28: =Daily!F140 -> #DIV/0! | G28: =Daily!G140 -> #DIV/0! | H28: =Daily!H140 -> #DIV/0! | I28: =Daily!I140
A29: =Daily!A145 -> 3/10/26 Weekly Total | B29: =Daily!B145 -> #DIV/0! | C29: =Daily!C145 -> #DIV/0! | D29: =Daily!D145 -> #DIV/0! | E29: =Daily!E145 -> #DIV/0! | F29: =Daily!F145 -> #DIV/0! | G29: =Daily!G145 -> #DIV/0! | H29: =Daily!H145 -> #DIV/0! | I29: =Daily!I145
A30: =Daily!A151 -> 3/16/26 Weekly Total | B30: =Daily!B151 -> #DIV/0! | C30: =Daily!C151 -> #DIV/0! | D30: =Daily!D151 -> #DIV/0! | E30: =Daily!E151 -> #DIV/0! | F30: =Daily!F151 -> #DIV/0! | G30: =Daily!G151 -> #DIV/0! | H30: =Daily!H151 -> #DIV/0! | I30: =Daily!I151
A31: =Daily!A157 -> 3/23/26 Weekly Total | B31: =Daily!B157 -> #DIV/0! | C31: =Daily!C157 -> #DIV/0! | D31: =Daily!D157 -> #DIV/0! | E31: =Daily!E157 -> #DIV/0! | F31: =Daily!F157 -> #DIV/0! | G31: =Daily!G157 -> #DIV/0! | H31: =Daily!H157 -> #DIV/0! | I31: =Daily!I157
A32: =Daily!A163 -> 4/6/26 Weekly Total | B32: =Daily!B163 -> #DIV/0! | C32: =Daily!C163 -> #DIV/0! | D32: =Daily!D163 -> #DIV/0! | E32: =Daily!E163 -> #DIV/0! | F32: =Daily!F163 -> #DIV/0! | G32: =Daily!G163 -> #DIV/0! | H32: =Daily!H163 -> #DIV/0! | I32: =Daily!I163
A33: =Daily!A169 -> 4/13/26 Weekly Total | B33: =Daily!B169 -> #DIV/0! | C33: =Daily!C169 -> #DIV/0! | D33: =Daily!D169 -> #DIV/0! | E33: =Daily!E169 -> #DIV/0! | F33: =Daily!F169 -> #DIV/0! | G33: =Daily!G169 -> #DIV/0! | H33: =Daily!H169 -> #DIV/0! | I33: =Daily!I169
A34: =Daily!A175 -> 4/20/26 Weekly Total | B34: =Daily!B175 -> #DIV/0! | C34: =Daily!C175 -> #DIV/0! | D34: =Daily!D175 -> #DIV/0! | E34: =Daily!E175 -> #DIV/0! | F34: =Daily!F175 -> #DIV/0! | G34: =Daily!G175 -> #DIV/0! | H34: =Daily!H175 -> #DIV/0! | I34: =Daily!I175
A35: =Daily!A181 -> 4/27/26 Weekly Total | B35: =Daily!B181 -> #DIV/0! | C35: =Daily!C181 -> #DIV/0! | D35: =Daily!D181 -> #DIV/0! | E35: =Daily!E181 -> #DIV/0! | F35: =Daily!F181 -> #DIV/0! | G35: =Daily!G181 -> #DIV/0! | H35: =Daily!H181 -> #DIV/0! | I35: =Daily!I181
A36: =Daily!A187 -> 5/4/26 Weekly Total | B36: =Daily!B187 -> #DIV/0! | C36: =Daily!C187 -> #DIV/0! | D36: =Daily!D187 -> #DIV/0! | E36: =Daily!E187 -> #DIV/0! | F36: =Daily!F187 -> #DIV/0! | G36: =Daily!G187 -> #DIV/0! | H36: =Daily!H187 -> #DIV/0! | I36: =Daily!I187
A37: =Daily!A193 -> 5/11/26 Weekly Total | B37: =Daily!B193 -> #DIV/0! | C37: =Daily!C193 -> #DIV/0! | D37: =Daily!D193 -> #DIV/0! | E37: =Daily!E193 -> #DIV/0! | F37: =Daily!F193 -> #DIV/0! | G37: =Daily!G193 -> #DIV/0! | H37: =Daily!H193 -> #DIV/0! | I37: =Daily!I193
A38: =Daily!A199 -> 5/18/26 Weekly Total | B38: =Daily!B199 -> #DIV/0! | C38: =Daily!C199 -> #DIV/0! | D38: =Daily!D199 -> #DIV/0! | E38: =Daily!E199 -> #DIV/0! | F38: =Daily!F199 -> #DIV/0! | G38: =Daily!G199 -> #DIV/0! | H38: =Daily!H199 -> #DIV/0! | I38: =Daily!I199
A39: =Daily!A204 -> 5/26/26 Weekly Total | B39: =Daily!B204 -> #DIV/0! | C39: =Daily!C204 -> #DIV/0! | D39: =Daily!D204 -> #DIV/0! | E39: =Daily!E204 -> #DIV/0! | F39: =Daily!F204 -> #DIV/0! | G39: =Daily!G204 -> #DIV/0! | H39: =Daily!H204 -> #DIV/0! | I39: =Daily!I204
A40: =Daily!A210 -> 6/1/26 Weekly Total | B40: =Daily!B210 -> #DIV/0! | C40: =Daily!C210 -> #DIV/0! | D40: =Daily!D210 -> #DIV/0! | E40: =Daily!E210 -> #DIV/0! | F40: =Daily!F210 -> #DIV/0! | G40: =Daily!G210 -> #DIV/0! | H40: =Daily!H210 -> #DIV/0! | I40: =Daily!I210

Sheet Elopment
A1: Date | B1: DD | C1: 9:00 Social Skills | D1: 9:30 Bridges | E1: 10:00 Math | F1: 10:30:00 AM DHH - math | G1: 11:00:00 AM Specials | H1: 11:30:00 AM -Specials | I1: 12:00 Whole Group Reading | J1: 12:30 DHH Reading | K1: 1:00 Recess | L1: 1:30 Lunch | M1: 2:00 Reading | N1: 2:30 Reading | O1: 3:00 Dismissal | P1: TOTAL | R1: Average In Class: | S1: =AVERAGEIF(R:R,">0") -> 0.83394378
A2: Totals from below: | C2: =countif(C3:C104, "<>") - COUNTIF(C3:C104, "in class") -> 10 | D2: =countif(D3:D104, "<>") - COUNTIF(D3:D104, "in class") -> 24 | E2: =countif(E3:E104, "<>") - COUNTIF(E3:E104, "in class") -> 25 | F2: =countif(F3:F104, "<>") - COUNTIF(F3:F104, "in class") -> 26 | G2: =countif(G3:G104, "<>") - COUNTIF(G3:G104, "in class") -> 25 | H2: =countif(H3:H104, "<>") - COUNTIF(H3:H104, "in class") -> 10 | I2: =countif(I3:I104, "<>") - COUNTIF(I3:I104, "in class") -> 18 | J2: =countif(J3:J104, "<>") - COUNTIF(J3:J104, "in class") -> 13 | ... O2: =countif(O3:O104, "<>") - COUNTIF(O3:O104, "in class") -> 14
A3: 45902 | C3: In class | D3: In class | E3: In class | F3: In class | G3: In class | H3: In class | I3: In class | J3: In class | K3: In class | L3: In class | M3: In class | N3: In class | O3: In class | P3: =COUNTIF(C3:O3,"In class") -> 13 | Q3: 13 | R3: =P3/Q3 -> 1 | S3: *none
A4: 45903 | C4: In class | D4: In class | E4: In class | F4: In class | G4: Mild | H4: In class | I4: In class | J4: In class | K4: In class | L4: In class | M4: In class | N4: In class | O4: In class | P4: =COUNTIF(C4:O4,"In class") -> 12 | Q4: 13 | R4: =P4/Q4 -> 0.92307692
A5: 45904 | C5: In class | D5: In class | E5: In class | F5: In class | G5: In class | H5: In class | I5: In class | J5: In class | K5: In class | L5: In class | M5: In class | N5: In class | O5: In class | P5: =COUNTIF(C5:O5,"In class") -> 13 | Q5: 13 | R5: =P5/Q5 -> 1 | S5: *none
A6: 45905 | C6: In class | D6: In class | E6: In class | F6: In class | G6: In class | H6: Mod | I6: In class | J6: In class | K6: In class | L6: In class | M6: In class | N6: In class | O6: In class | P6: =COUNTIF(C6:O6,"In class") -> 12 | Q6: 13 | R6: =P6/Q6 -> 0.92307692
A7: 45908 | C7: In class | D7: In class | E7: In class | F7: In class | G7: In class | H7: In class | I7: In class | J7: In class | K7: In class | L7: In class | M7: In class | N7: In class | O7: In class | P7: =COUNTIF(C7:O7,"In class") -> 13 | Q7: 13 | R7: =P7/Q7 -> 1 | S7: *none
A8: 45909 | C8: In class | D8: In class | E8: In class | F8: In class | G8: In class | H8: In class | I8: In class | J8: In class | K8: Mild | L8: In class | M8: In class | N8: In class | O8: In class | P8: =COUNTIF(C8:O8,"In class") -> 12 | Q8: 13 | R8: =P8/Q8 -> 0.92307692
A9: 45910 | C9: In class | D9: In class | E9: In class | F9: In class | G9: In class | H9: Mod | I9: In class | J9: In class | K9: In class | L9: In class | M9: In class | N9: In class | O9: In class | P9: =COUNTIF(C9:O9,"In class") -> 12 | Q9: 13 | R9: =P9/Q9 -> 0.92307692
A10: 45911 | C10: In class | D10: In class | E10: In class | F10: In class | G10: In class | H10: In class | I10: In class | J10: In class | K10: In class | L10: In class | M10: In class | N10: In class | O10: In class | P10: =COUNTIF(C10:O10,"In class") -> 13 | Q10: 13 | R10: =P10/Q10 -> 1 | S10: *none
A11: 45912 | C11: In class | D11: Mild | E11: In class | F11: In class | G11: In class | H11: In class | I11: In class | J11: In class | K11: In class | L11: In class | P11: =COUNTIF(C11:O11,"In class") -> 9 | Q11: 10 | R11: =P11/Q11 -> 0.9 | S11: *left early
A12: 45915 | C12: Mild | D12: In class | E12: In class | F12: In class | G12: In class | H12: In class | I12: In class | J12: In class | K12: In class | L12: In class | M12: In class | N12: In class | O12: In class | P12: =COUNTIF(C12:O12,"In class") -> 12 | Q12: 13 | R12: =P12/Q12 -> 0.92307692
A13: 45916 | C13: Mild | D13: Mild | E13: Mod | F13: Mild | G13: In class | H13: In class | I13: In class | J13: In class | K13: In class | L13: In class | M13: In class | N13: In class | O13: In class | P13: =COUNTIF(C13:O13,"In class") -> 9 | Q13: 13 | R13: =P13/Q13 -> 0.69230769
A14: 45917 | C14: In class | D14: In class | E14: In class | F14: In class | G14: In class | H14: In class | I14: In class | J14: In class | K14: In class | L14: In class | M14: In class | N14: In class | O14: In class | P14: =COUNTIF(C14:O14,"In class") -> 13 | Q14: 13 | R14: =P14/Q14 -> 1 | S14: *none
A15: 45918 | C15: In class | D15: In class | E15: In class | F15: Mild | G15: Mod | H15: In class | I15: In class | J15: In class | K15: Mild | L15: In class | M15: In class | N15: In class | O15: In class | P15: =COUNTIF(C15:O15,"In class") -> 10 | Q15: 13 | R15: =P15/Q15 -> 0.76923077
A16: 45919 | C16: In class | D16: Mod | E16: In class | F16: Mild | G16: In class | H16: In class | I16: In class | J16: In class | K16: In class | L16: In class | M16: In class | N16: In class | O16: In class | P16: =COUNTIF(C16:O16,"In class") -> 11 | Q16: 13 | R16: =P16/Q16 -> 0.84615385
A17: 45922 | C17: In class | D17: In class | E17: Mild | F17: In class | G17: In class | H17: In class | I17: In class | J17: In class | K17: In class | L17: In class | M17: In class | N17: In class | O17: In class | P17: =COUNTIF(C17:O17,"In class") -> 12 | Q17: 13 | R17: =P17/Q17 -> 0.92307692
A18: 45923 | C18: In class | D18: Mild | E18: In class | F18: Mod | G18: In class | H18: In class | I18: In class | J18: In class | K18: Mild | L18: In class | M18: In class | N18: In class | O18: In class | P18: =COUNTIF(C18:O18,"In class") -> 10 | Q18: 13 | R18: =P18/Q18 -> 0.76923077
A19: 45924 | C19: In class | D19: Mild | E19: Mod | F19: In class | G19: In class | H19: In class | I19: In class | J19: In class | K19: Mod | L19: In class | M19: In class | N19: Mild | O19: In class | P19: =COUNTIF(C19:O19,"In class") -> 9 | Q19: 13 | R19: =P19/Q19 -> 0.69230769
A20: 45925 | C20: In class | D20: In class | E20: In class | F20: Mod | G20: In class | H20: In class | I20: In class | J20: In class | K20: In class | L20: Mild | M20: In class | N20: In class | O20: In class | P20: =COUNTIF(C20:O20,"In class") -> 11 | Q20: 13 | R20: =P20/Q20 -> 0.84615385
A21: 45926 | C21: In class | D21: Mod | E21: In class | F21: In class | G21: In class | H21: In class | I21: In class | J21: In class | K21: In class | L21: In class | M21: Mod | N21: In class | O21: In class | P21: =COUNTIF(C21:O21,"In class") -> 11 | Q21: 13 | R21: =P21/Q21 -> 0.84615385
A22: 45929 | C22: Mod | D22: In class | E22: Mild | F22: In class | G22: In class | H22: In class | I22: In class | J22: In class | K22: In class | L22: In class | M22: In class | N22: In class | O22: In class | P22: =COUNTIF(C22:O22,"In class") -> 11 | Q22: 13 | R22: =P22/Q22 -> 0.84615385
A23: 45930 | C23: In class | D23: In class | E23: In class | F23: In class | G23: In class | H23: In class | I23: In class | J23: In class | K23: In class | L23: Mild | M23: Severe | N23: Mod | O23: In class | P23: =COUNTIF(C23:O23,"In class") -> 10 | Q23: 13 | R23: =P23/Q23 -> 0.76923077
A24: 45931 | C24: Mod | D24: Mod | E24: In class | F24: In class | G24: In class | H24: In class | I24: In class | J24: In class | K24: In class | L24: In class | M24: In class | N24: In class | O24: Mild | P24: =COUNTIF(C24:O24,"In class") -> 10 | Q24: 13 | R24: =P24/Q24 -> 0.76923077
A25: 45932 | C25: In class | D25: In class | E25: In class | F25: In class | G25: In class | H25: In class | I25: In class | J25: In class | K25: Mod | L25: Mod | M25: Mod | N25: In class | O25: In class | P25: =COUNTIF(C25:O25,"In class") -> 10 | Q25: 13 | R25: =P25/Q25 -> 0.76923077
A26: 45933 | C26: In class | D26: In class | E26: In class | F26: In class | G26: In class | H26: In class | I26: In class | J26: In class | K26: In class | L26: In class | M26: In class | N26: In class | O26: In class | P26: =COUNTIF(C26:O26,"In class") -> 13 | Q26: 13 | R26: =P26/Q26 -> 1
A27: 45937 | C27: In class | D27: In class | E27: In class | F27: In class | G27: In class | H27: In class | I27: In class | J27: In class | P27: =COUNTIF(C27:O27,"In class") -> 8 | Q27: 8 | R27: =P27/Q27 -> 1 | T27: Left early
A28: 45938 | C28: In class | D28: In class | E28: In class | F28: In class | G28: In class | H28: In class | I28: In class | J28: In class | K28: In class | L28: In class | M28: In class | N28: In class | O28: Mild | P28: =COUNTIF(C28:O28,"In class") -> 12 | Q28: 13 | R28: =P28/Q28 -> 0.92307692
A29: 45939 | C29: In class | D29: In class | E29: In class | F29: In class | G29: In class | H29: In class | I29: In class | J29: In class | K29: In class | L29: In class | M29: In class | N29: Mild | O29: In class | P29: =COUNTIF(C29:O29,"In class") -> 12 | Q29: 13 | R29: =P29/Q29 -> 0.92307692
A30: 45940 | C30: In class | D30: In class | E30: Mod | F30: In class | G30: Mod | H30: In class | I30: In class | J30: In class | K30: In class | L30: In class | M30: In class | N30: In class | O30: In class | P30: =COUNTIF(C30:O30,"In class") -> 11 | Q30: 13 | R30: =P30/Q30 -> 0.84615385
A31: 45943 | C31: Mod | D31: Mod | E31: Mod | F31: In class | G31: Mod | H31: Mod | I31: In class | J31: In class | K31: In class | L31: In class | M31: In class | N31: In class | O31: In class | P31: =COUNTIF(C31:O31,"In class") -> 8 | Q31: 13 | R31: =P31/Q31 -> 0.61538462
A32: 45944 | C32: In class | D32: In class | E32: In class | F32: In class | G32: In class | H32: In class | I32: In class | J32: In class | K32: In class | L32: In class | M32: In class | N32: In class | O32: In class | P32: =COUNTIF(C32:O32,"In class") -> 13 | Q32: 13 | R32: =P32/Q32 -> 1
A33: 45945 | C33: In class | D33: In class | E33: Mod | F33: In class | G33: In class | H33: In class | I33: In class | J33: In class | K33: In class | L33: In class | M33: In class | N33: In class | O33: In class | P33: =COUNTIF(C33:O33,"In class") -> 12 | Q33: 13 | R33: =P33/Q33 -> 0.92307692
A34: 45951 | C34: In class | D34: In class | E34: In class | F34: In class | G34: Mild | H34: In class | I34: In class | J34: In class | K34: In class | L34: In class | M34: In class | N34: Mod | O34: In class | P34: =COUNTIF(C34:O34,"In class") -> 11 | Q34: 13 | R34: =P34/Q34 -> 0.84615385
A35: 45952 | C35: In class | D35: Mild | E35: In class | F35: In class | G35: In class | H35: In class | I35: In class | J35: Mod | K35: In class | L35: In class | M35: In class | N35: In class | O35: In class | P35: =COUNTIF(C35:O35,"In class") -> 11 | Q35: 13 | R35: =P35/Q35 -> 0.84615385
A36: 45953 | C36: In class | D36: In class | E36: Mild | F36: In class | G36: In class | H36: In class | I36: In class | J36: In class | K36: In class | L36: In class | M36: Mild | N36: Mod | O36: In class | P36: =COUNTIF(C36:O36,"In class") -> 10 | Q36: 13 | R36: =P36/Q36 -> 0.76923077
A37: 45954 | C37: In class | D37: In class | E37: Mod | F37: In class | G37: In class | H37: In class | I37: In class | J37: In class | K37: In class | L37: In class | M37: In class | N37: In class | O37: In class | P37: =COUNTIF(C37:O37,"In class") -> 12 | Q37: 13 | R37: =P37/Q37 -> 0.92307692
A38: 45957 | C38: In class | D38: In class | E38: In class | F38: In class | G38: In class | H38: In class | I38: In class | J38: In class | K38: In class | L38: Mild | M38: Mild | N38: Mild | O38: Mild | P38: =COUNTIF(C38:O38,"In class") -> 9 | Q38: 13 | R38: =P38/Q38 -> 0.69230769
A39: 45958 | C39: In class | D39: In class | E39: In class | F39: In class | G39: In class | H39: In class | I39: Mod | J39: In class | K39: In class | L39: In class | M39: Mod | N39: In class | O39: Mod | P39: =COUNTIF(C39:O39,"In class") -> 10 | Q39: 13 | R39: =P39/Q39 -> 0.76923077
... A47: 45968 | C47: In class | D47: In class | E47: In class | F47: In class | G47: In class | H47: In class | I47: In class | J47: In class | K47: In class | L47: In class | M47: Mild | N47: In class | O47: In class | P47: =COUNTIF(C47:O47,"In class") -> 12 | Q47: 13 | R47: =P47/Q47 -> 0.92307692
...

Sheet Sheet3
